Exception on /callback [GET]
Traceback (most recent call last):
  File "/home/lauraallobe/hackerNews/hackernews/routes.py", line 148, in callback
    if currentSess.userinfo:
AttributeError: 'OAuth2Token' object has no attribute 'userinfo'

During handling of the above exception, another exception occurred:

Traceback (most recent call last):
  File "/home/lauraallobe/hackerNews/venv/lib/python3.10/site-packages/flask/app.py", line 1455, in wsgi_app
    response = self.full_dispatch_request()
  File "/home/lauraallobe/hackerNews/venv/lib/python3.10/site-packages/flask/app.py", line 869, in full_dispatch_request
    rv = self.handle_user_exception(e)
  File "/home/lauraallobe/hackerNews/venv/lib/python3.10/site-packages/flask/app.py", line 867, in full_dispatch_request
    rv = self.dispatch_request()
  File "/home/lauraallobe/hackerNews/venv/lib/python3.10/site-packages/flask/app.py", line 852, in dispatch_request
    return self.ensure_sync(self.view_functions[rule.endpoint])(**view_args)
  File "/home/lauraallobe/hackerNews/hackernews/routes.py", line 178, in callback
    except (DatabaseError, DataError, OperationalError) as e:
NameError: name 'DatabaseError' is not defined
